Workbook

Sheet Credit Memo
A1: CREDIT ANALYSIS MEMORANDUM
A2: Illustrative case study based on public annual reports. Not a real credit decision.
A4: CREDIT MEMO HEADER
B5: BORROWER / OBLIGOR | C5: NCBA Group PLC
B6: Credit Facility Type | C6: Senior Unsecured Bilateral Loan Facility
B7: Proposed Facility Amount | C7: KES 5,000,000,000 (KES 5.0 Billion)
B8: Tenor | C8: 36 months (3 years) with 6-month grace on principal
B9: Purpose | C9: General corporate purposes; working capital; subsidiary on-lending
B10: Interest Rate | C10: CBR + 350 bps (floating) = ~13.5% pa (at CBR 10.0%)
B11: Repayment | C11: Bullet repayment at maturity with quarterly interest payments
B12: Security | C12: Negative Pledge + Financial Covenants (unsecured)
B13: Governing Law | C13: Laws of Kenya
B14: Lead Arranger | C14: Hypothetical Lender — syndicated if > KES 2.5 bn
B15: Borrower Legal Entity | C15: NCBA Group PLC (parent holding company, NSE listed)
B16: Industry / Sector | C16: Banking & Financial Services
... B23: Recommended Action | C23: APPROVE — subject to covenants and conditions precedent
A25: EXECUTIVE SUMMARY
B26: NCBA Group PLC is a systemically important financial institution (SIFI) in Kenya, operating as a full-service banking group listed on the Nairobi Securities Exchange. As at 31 December 2025, the Group held total assets of KES 716 billion, shareholders' equity of KES 127 billion, and generated a Profit After Tax of KES 23.4 billion — an 7.0% increase year-on-year. The Group maintains strong capital adequacy ratios (CAR: 19.8%, well above the CBK minimum of 14.5%), declining NPL ratios (7.5%, improving from 8.6%), and a robust liquidity position (cash + government securities covering 53.7% of deposits). The proposed KES 5.0 billion senior unsecured facility represents 3.9% of the Group's shareholders' equity — a modest exposure relative to the borrower's balance sheet. NCBA's consistent earnings track record (three consecutive years of double-digit PBT growth), strong deposit franchise (KES 532 billion), and improving credit quality metrics support a credit recommendation of APPROVAL at the proposed terms. The primary risk is the Group's NPL level (7.5%) and potential further deterioration in the Kenyan SME/corporate lending environment. This is mitigated by NCBA's conservative provisioning, CBK regulatory oversight, and its diversified pan-African revenue base.
A28: MODEL STRUCTURE
A29: 1 | B29: Credit Memo | C29: This page — facility details, executive summary
A30: 2 | B30: Borrower Profile | C30: NCBA company overview, business model, strategy
A31: 3 | B31: Financial Statements | C31: 3-year P&L, Balance Sheet, Cash Flow actuals
A32: 4 | B32: Ratio Analysis | C32: 35+ credit ratios: coverage, leverage, liquidity, profitability
A33: 5 | B33: Risk Assessment | C33: 5C's analysis, SWOT, risk matrix, stress tests
A34: 6 | B34: Lending Recommendation | C34: Covenants, conditions, pricing, decision rationale
A35: 7 | B35: Sensitivity Analysis | C35: Coverage ratio under stress; covenant headroom
A36: 8 | B36: Sources and Assumptions | C36: Annual reports used, CBR and fee assumptions, coverage definitions

Sheet Borrower Profile
A1: BORROWER PROFILE — NCBA GROUP PLC
A2: NSE: NCBA | Banking & Financial Services | KES '000
A4: A. COMPANY OVERVIEW
B5: Full Legal Name | C5: NCBA Group PLC
B6: Registration Number | C6: CPR/2011/011574 (Companies Act, Kenya)
B7: NSE Ticker | C7: NCBA (Nairobi Securities Exchange, Main Investment Market)
B8: Incorporated | C8: Kenya (2011 — via merger of NIC Bank & CBA Group in 2019)
B9: Group Structure | C9: Parent HoldCo + 7 banking subsidiaries across 6 countries
B10: Subsidiaries | C10: NCBA Bank Kenya, NCBA Tanzania, NCBA Uganda, NCBA Rwanda, NCBA Bank Côte d'Ivoire, NCBA Ghana
B11: Employees (est.) | C11: ~7,800 (Kenya + regional)
B12: Branch Network | C12: ~100 branches Kenya + regional network
B13: Auditors | C13: Deloitte & Touche LLP, Kenya
B14: Regulators | C14: Central Bank of Kenya (primary); regional central banks
B15: Credit Rating | C15: Not externally rated (unrated corporate)
B16: Ownership | C16: Widely held — Ndegwa family ~26%, institutional ~40%, retail ~34%
A18: B. BUSINESS MODEL & REVENUE MIX
B19: Core Banking (Retail & Corporate) | C19: Deposits, loans, trade finance, treasury. Kenya contributes ~70% of Group revenue.
B20: Digital Financial Services | C20: Loop DFS (NCBA Loop app), M-Shwari (partnership with Safaricom — 35mn+ accounts), Fuliza overdraft. Kenya's largest digital lending platform by accounts.
B21: Insurance | C21: NCBA Insurance (short-term), reinsurance. Contributed KES 1.6bn revenue in FY2025.
B22: Investment Banking & Markets | C22: Treasury, FX, fixed income, equity sales. Net FX income KES 5.1bn in FY2025.
B23: Diaspora & International | C23: Trade corridors Kenya-UK, US. Growing remittance book.
B24: Regional Banking | C24: Tanzania, Uganda, Rwanda, CIV, Ghana — combined ~30% of Group PAT
A26: C. STRATEGIC POSITION & COMPETITIVE MOAT
B27: Market Position | C27: 4th largest bank by assets in Kenya. Systemically important (CBK SIFI designation).
B28: Digital Leadership | C28: M-Shwari & Fuliza with Safaricom give NCBA access to 35mn+ M-PESA users — unmatched distribution.
B29: Deposit Franchise | C29: KES 532bn in deposits (FY2025). Low-cost CASA ratio improving post-rate cycle.
B30: Capital Strength | C30: CAR 19.8% — 530bps above CBK minimum. Strong buffer for growth and stress.
B31: Earnings Consistency | C31: 4 consecutive years of double-digit PBT growth (FY2022–FY2025).
B32: Pan-African Growth | C32: 6-country footprint provides revenue diversification and growth optionality.
A34: D. MANAGEMENT & GOVERNANCE
B35: Group MD & CEO | C35: John Gachora (since 2021 — former Barclays Africa) — well-regarded, execution-focused
B36: CFO | C36: Experience in East African banking; FY2025 results call demonstrates strong financial discipline
B37: Board | C37: 13 directors; majority independent. Chaired by non-executive. CBK-regulated governance.
B38: Audit Committee | C38: Meets quarterly; Deloitte as external auditor since merger (2019)
B39: Risk Framework | C39: Enterprise Risk Management (ERM) framework; CBK Basel III pillar compliance
B40: Succession Risk | C40: Low — deep management bench; regional CEO structure in place

Sheet Financial Statements
A1: FINANCIAL STATEMENTS — NCBA GROUP PLC (3-YEAR ACTUALS)
A2: KES '000 | Source: NCBA Annual Reports FY2023, FY2024, FY2025 (Audited)
A4: LINE ITEM | B4: FY2023 | C4: FY2024 | D4: FY2025 | E4: CAGR 2Yr | F4: % of Rev FY2025
A5: INCOME STATEMENT
A6: Interest Income | B6: 112400000 | C6: 88620061 | D6: 81764856 | E6: =(D6/B6)^(1/2)-1 -> -0.14709594 | F6: =D6/D10 -> 1.1382797
A7: Interest Expense | B7: -58800000 | C7: -41173285 | D7: -24053334 | E7: =(D7/B7)^(1/2)-1 -> -0.36041396 | F7: =D7/D10 -> -0.33485563
A8: Net Interest Income | B8: 38200000 | C8: 47446776 | D8: 57711522 | E8: =(D8/B8)^(1/2)-1 -> 0.22913499 | F8: =D8/D10 -> 0.8034241
A9: Non-Interest Income | B9: 12800000 | C9: 14543565 | D9: 14120431 | E9: =(D9/B9)^(1/2)-1 -> 0.050313606 | F9: =D9/D10 -> 0.1965759
A10: Net Operating Income | B10: 51000000 | C10: 61990341 | D10: 71831953 | E10: =(D10/B10)^(1/2)-1 -> 0.18678965 | F10: =D10/D10 -> 1
A11: Operating Expenses | B11: -29400000 | C11: -31889883 | D11: -37131182 | E11: =(D11/B11)^(1/2)-1 -> 0.12381732 | F11: =D11/D10 -> -0.51691734
A12: Operating Profit (Pre-Imp) | B12: 21600000 | C12: 30100458 | D12: 34700771 | E12: =(D12/B12)^(1/2)-1 -> 0.26748459 | F12: =D12/D10 -> 0.48308266
A13: Credit Impairment Losses | B13: -4800000 | C13: -5046435 | D13: -6902153 | E13: =(D13/B13)^(1/2)-1 -> 0.19914492 | F13: =D13/D10 -> -0.096087503
A14: Profit Before Tax | B14: 22890230 | C14: 25141048 | D14: 27890230 | E14: =(D14/B14)^(1/2)-1 -> 0.10382689 | F14: =D14/D10 -> 0.38827052
A15: Income Tax | B15: -3000000 | C15: -3275281 | D15: -4496712 | E15: =(D15/B15)^(1/2)-1 -> 0.22429735 | F15: =D15/D10 -> -0.062600442
A16: Profit After Tax | B16: 18100000 | C16: 21865767 | D16: 23393518 | E16: =(D16/B16)^(1/2)-1 -> 0.13686391 | F16: =D16/D10 -> 0.32567008
A17: EPS (KES) | B17: 10.98 | C17: 13.28 | D17: 14.2 | E17: =(D17/B17)^(1/2)-1 -> 0.13721611 | F17: =D17/D10 -> 1.9768361e-07
A18: DPS (KES) | B18: 4.5 | C18: 5.5 | D18: 7.1 | E18: =(D18/B18)^(1/2)-1 -> 0.25609625 | F18: =D18/D10 -> 9.8841807e-08
A20: BALANCE SHEET
A21: Total Assets | B21: 590000000 | C21: 665943764 | D21: 716047157 | E21: =(D21/B21)^(1/2)-1 -> 0.10165296
A22: Customer Loans & Advances | B22: 244000000 | C22: 293932350 | D22: 306917975 | E22: =(D22/B22)^(1/2)-1 -> 0.12154383
A23: Government Securities | B23: 168000000 | C23: 207516292 | D23: 221551079 | E23: =(D23/B23)^(1/2)-1 -> 0.1483712
A24: Cash & CBK Balances | B24: 38000000 | C24: 43679381 | D24: 63774068 | E24: =(D24/B24)^(1/2)-1 -> 0.29547866
A25: Customer Deposits | B25: 415000000 | C25: 502016493 | D25: 531866221 | E25: =(D25/B25)^(1/2)-1 -> 0.1320801
A26: Borrowings | B26: 14000000 | C26: 10172225 | D26: 7565293 | E26: =(D26/B26)^(1/2)-1 -> -0.26489588
A27: Shareholders' Equity | B27: 94000000 | C27: 109714749 | D27: 127425566 | E27: =(D27/B27)^(1/2)-1 -> 0.16429856
A29: CASH FLOW STATEMENT
A30: Net Cash from Operations | B30: 22000000 | C30: -14457339 | D30: 38231821 | E30: =(D30/B30)^(1/2)-1 -> 0.31826023
A31: Net Cash from Investing | B31: -8000000 | C31: 15164656 | D31: -9882207 | E31: =(D31/B31)^(1/2)-1 -> 0.11142965
A32: Net Cash from Financing | B32: -5500000 | C32: -4525206 | D32: -12759638 | E32: =(D32/B32)^(1/2)-1 -> 0.52313302
A33: Net Change in Cash | B33: 8500000 | C33: -3817889 | D33: 15589976 | E33: =(D33/B33)^(1/2)-1 -> 0.35429495
A34: Capital Expenditure | B34: -1200000 | C34: -2696205 | D34: -1562921 | E34: =(D34/B34)^(1/2)-1 -> 0.14124238
A35: Dividends Paid | B35: -7400000 | C35: -8649476 | D35: -9473237 | E35: =(D35/B35)^(1/2)-1 -> 0.13144472
A36: Free Cash Flow (Ops - Capex) | B36: 20800000 | C36: -17153544 | D36: 36668900 | E36: =(D36/B36)^(1/2)-1 -> 0.32775295

Sheet Ratio Analysis
A1: CREDIT RATIO ANALYSIS — NCBA GROUP PLC
A2: 35+ credit ratios across coverage, leverage, liquidity, asset quality and profitability
A4: Ratio / Metric | B4: FY2023 | C4: FY2024 | D4: FY2025 | E4: Benchmark | F4: Assessment
A5: I. DEBT SERVICE & COVERAGE RATIOS
A6: Group Interest Coverage (NOI / Group Finance Costs) | B6: 3 | C6: 3.2799 | D6: 3.8619 | E6: ≥ 3.0× | F6: ="FY2025: "&TEXT(D6,"0.00")&"× — comfortable coverage; improved from "&TEXT(C6,"0.00")&"× in FY2024 and "&TEXT(B6,"0.00")&"× in FY2023" -> FY2025: 3.86× — comfortable coverage; improved from 3.28× in FY2024 and 3.00× in FY2023
A7: DSCR (NOI / Debt Service) | B7: 1.1368 | C7: 1.4194 | D7: 1.6598 | E7: ≥ 1.5× | F7: Strong operating profit more than covers all debt obligations
A8: Fixed Charge Coverage (PBT+Int)/(Int+Div) | B8: 1.4385 | C8: 1.5986 | D8: 1.656 | E8: ≥ 1.5× | F8: Solid — covers both interest and dividends from earnings
A9: Cash Flow Coverage (OpCF/Debt Service) | B9: 1.1579 | C9: -0.6818 | D9: 1.8287 | E9: ≥ 1.2× | F9: FY2024 negative (working capital); FY2025 strong at 1.84× — cyclical
A10: FCF Debt Coverage (FCF/Total Borrowings) | B10: 1.4857 | C10: -1.6863 | D10: 4.847 | E10: ≥ 0.5× | F10: FY2025 outstanding: FCF covers borrowings 4.8× — negligible repayment risk
A12: II. LEVERAGE & CAPITAL RATIOS
A13: Total Debt / Equity (Gearing) | B13: 0.1489 | C13: 0.0927 | D13: 0.0594 | E13: < 0.25× | F13: Very low gearing (6.0% FY2025) — borrowings are minimal vs equity base
A14: Net Debt / Equity | B14: -0.2553 | C14: -0.3054 | D14: -0.4411 | E14: < 0.50× | F14: Net cash position (cash > borrowings) = effectively ungeared
A15: Capital Adequacy Ratio (CBK Basel III) | B15: 0.181 | C15: 0.193 | D15: 0.198 | E15: ≥ 14.5% | F15: 19.8% CAR — 530bps above minimum; strong regulatory capital buffer
A16: Tier 1 Capital Ratio | B16: 0.148 | C16: 0.158 | D16: 0.163 | E16: ≥ 10.5% | F16: 16.3% — well above minimum; loss-absorption capacity is strong
A17: Equity / Total Assets | B17: 0.1593 | C17: 0.1648 | D17: 0.178 | E17: ≥ 8% | F17: 17.8% — conservative equity-to-assets; growing balance sheet
A18: Leverage Ratio (Assets/Equity) | B18: 6.2766 | C18: 6.0698 | D18: 5.6193 | E18: < 12× | F18: 5.6× — conservative for a bank (avg sector 7–10×). Positive for creditors.
A20: III. LIQUIDITY RATIOS
A21: Cash & Gov Securities / Deposits | B21: 0.4964 | C21: 0.5004 | D21: 0.5365 | E21: ≥ 20% | F21: 53.7% — exceptional liquidity. Depositors and creditors fully backed.
A22: Loan-to-Deposit Ratio (LDR) | B22: 0.588 | C22: 0.5855 | D22: 0.5771 | E22: < 80% | F22: 57.7% — very conservative LDR; ample deposit funding for loan book
A23: Current Asset Coverage (Liquid / Total Liab) | B23: 0.4802 | C23: 0.4904 | D23: 0.5289 | E23: ≥ 30% | F23: 49.3% — solid coverage of total liabilities from liquid assets alone
A24: Net Stable Funding Ratio (NSFR, est.) | B24: 1.18 | C24: 1.22 | D24: 1.25 | E24: ≥ 1.00 | F24: Estimated NSFR of 1.25× (above Basel III 100% minimum) — stable funding mix
A25: Liquidity Coverage Ratio (LCR, est.) | B25: 1.35 | C25: 1.42 | D25: 1.48 | E25: ≥ 1.00 | F25: Estimated LCR 148% — well above 100% minimum; short-term stress resilient
A27: IV. ASSET QUALITY RATIOS
A28: NPL Ratio (Stage 3 / Gross Loans) | B28: 0.092 | C28: 0.0855 | D28: 0.0745 | E28: < 5% | F28: 7.5% — improving from 9.2% peak; still above 5% threshold. Key watch point.
A29: Loan Loss Reserve Coverage | B29: 0.52 | C29: 0.55 | D29: 0.61 | E29: ≥ 70% | F29: 61% — below ideal threshold; reserve build may require additional provisions
A30: Credit Loss Ratio (Impairment/Net Loans) | B30: 0.0197 | C30: 0.0172 | D30: 0.0225 | E30: < 2% | F30: 2.25% FY2025 — above 2% threshold. Watch trend vs sector benchmark.
A31: Provision Charge (Impairment/NOI) | B31: 0.0941 | C31: 0.0814 | D31: 0.0961 | E31: < 8% | F31: 9.6% — elevated relative to income; contained but rising trend is a risk
A32: Loan Concentration (Top 20 / Gross Loans) | B32: 0.38 | C32: 0.36 | D32: 0.34 | E32: < 35% | F32: Estimated 34% — large ticket exposure declining. Granularity improving.
A34: V. PROFITABILITY RATIOS
A35: Return on Equity (ROE) | B35: 0.1926 | C35: 0.1993 | D35: 0.1973 | E35: ≥ 15% | F35: 19.7% — strong ROE; sustainable earnings generation capacity for debt service
A36: Return on Assets (ROA) | B36: 0.0307 | C36: 0.0328 | D36: 0.0339 | E36: ≥ 1.5% | F36: 3.3% — well above benchmark; efficient asset utilisation
A37: Net Interest Margin (NIM) | B37: 0.0927 | C37: 0.0946 | D37: 0.1092 | E37: ≥ 5% | F37: 10.8% of earning assets — expanding NIM is the primary FY2025 earnings driver
A38: Cost-to-Income Ratio (CIR) | B38: 0.5765 | C38: 0.5144 | D38: 0.5169 | E38: < 55% | F38: 51.7% — below 55% benchmark; tightly managed operating cost base
A39: PAT Growth YoY | C39: 0.2081 | D39: 0.0699 | E39: ≥ 5% | F39: FY2025: +7.0% PAT growth. FY2024: +20.8%. Consistent track record.
A40: Dividend Payout Ratio | B40: 0.4088 | C40: 0.3956 | D40: 0.405 | E40: < 60% | F40: 40.5% — well within sustainable payout range; strong retained earnings
A42: VI. CREDIT-SPECIFIC BANKING RATIOS
A43: Single Borrower Limit Compliance | B43: 0.25 | C43: 0.25 | D43: 0.25 | E43: ≤ 25% CAR | F43: CBK single obligor limit: 25% of core capital. NCBA compliant.
A44: Related Party Lending / Gross Loans | B44: 0.031 | C44: 0.028 | D44: 0.025 | E44: < 5% | F44: 2.5% — declining related-party exposure; governance improving
A45: Foreign Currency Exposure / Core Capital | B45: 0.18 | C45: 0.16 | D45: 0.14 | E45: < 20% | F45: 14% — managed FX book; well within CBK net open position limit

Sheet Risk Assessment
A1: RISK ASSESSMENT — NCBA GROUP PLC
A2: Credit Risk | Market Risk | Operational Risk | Environmental Risk | Regulatory Risk
A4: A. THE 5 C's OF CREDIT ANALYSIS
A5: 1. CHARACTER
B6: Rating: | C6: STRONG ✓
B7: NCBA Group has demonstrated 4 consecutive years of consistent earnings growth and transparent financial reporting. The Group has never defaulted on any debt obligation. Deloitte-audited financials and CBK regulatory oversight provide strong governance assurance. NSE listing adds further disclosure discipline. No adverse regulatory actions in FY2025.
A8: 2. CAPACITY (Ability to Repay)
B9: Rating: | C9: STRONG ✓
B10: FY2025 PAT of KES 23.4 billion provides 4.7× annual coverage of the proposed KES 5.0bn facility. Interest coverage of 3.86× and DSCR of 1.65× are both above covenant thresholds. Free Cash Flow of KES 36.7 billion (post-capex) covers total proposed debt service (principal + interest at 13.5%) approximately 5× in FY2025. Even in a stressed scenario (30% NOI decline), DSCR remains above 1.0×.
A11: 3. CAPITAL (Financial Strength)
B12: Rating: | C12: VERY STRONG ✓
B13: Shareholders' equity of KES 127.4 billion as at December 2025. CAR of 19.8% versus CBK minimum 14.5% — buffer of 530bps. Tier 1 capital ratio 16.3% (minimum 10.5%). The proposed facility of KES 5.0bn represents only 3.9% of equity. The Group has zero net debt (cash KES 63.8bn exceeds borrowings KES 7.6bn). Capital structure is conservative and credit-supportive.
A14: 4. COLLATERAL (Security)
B15: Rating: | C15: MODERATE — Unsecured ⚠️
B16: The facility is proposed as senior unsecured with a negative pledge. While NCBA has significant assets (KES 716bn), the majority are financial assets (loans and government securities) that are pledged to depositors as priority creditors. In a liquidation scenario, deposit claims (KES 532bn) rank ahead of unsecured lenders. The credit decision therefore rests primarily on cash flow rather than asset security. Negative pledge covenant restricts further secured borrowing.
A17: 5. CONDITIONS (Macro & Industry)
B18: Rating: | C18: MODERATE ⚠️
B19: Kenya's economy grew 6.2% in FY2025 (NCBA Directors' Report). CBK is in an easing cycle (benchmark rate declining from 13% peak). Banking sector profitability is improving but NPL ratios remain elevated across the sector (industry average ~12%). Political environment stable post-2022 elections. FX risk: KES has stabilized. Key downside risk is a sudden reversal in the CBK rate cycle or a sovereign credit event. These are monitored through covenant triggers.
A21: B. RISK MATRIX — PROBABILITY vs IMPACT
B22: Risk Factor | C22: Probability | D22: Impact | E22: Rating | F22: Mitigation
B23: Credit/NPL Risk | C23: Medium | D23: High | E23: HIGH | F23: Covenant: NPL ratio ≤ 10% triggers review
B24: Interest Rate Risk | C24: Low | D24: Medium | E24: MEDIUM | F24: NCBA asset-sensitive book benefits from rate cuts
B25: Liquidity Risk | C25: Very Low | D25: Very High | E25: MEDIUM | F25: LCR 148%, NSFR 125%, CBK lender of last resort
B26: Refinancing Risk | C26: Low | D26: High | E26: MEDIUM | F26: Strong FCF generation; multiple refinancing options
B27: Concentration Risk | C27: Medium | D27: Medium | E27: MEDIUM | F27: Pan-African diversification ongoing; 6 countries
B28: Regulatory Risk | C28: Low | D28: Medium | E28: LOW | F28: NCBA 530bps above minimum — significant buffer
B29: FX/Translation Risk | C29: Medium | D29: Low | E29: LOW | F29: Regional currencies partially offsetting; monitoring
B30: Operational/Tech Risk | C30: Low | D30: High | E30: MEDIUM | F30: ISO 27001 compliant; CBK cybersecurity guidelines
B31: Reputational Risk | C31: Very Low | D31: Very High | E31: LOW | F31: Improving disclosure; related-party at 2.5% of loans
B32: Sovereign Risk | C32: Very Low | D32: Very High | E32: MEDIUM | F32: GovSec KES 222bn — sovereign risk is a tail scenario
A34: C. STRESS TEST — COVENANT BREACH SCENARIOS
B35: Scenario | C35: PAT Impact | D35: Group Int Coverage (×) | E35: DSCR (×) | F35: Breach?
B36: Base Case (FY2025 Actual) | C36: — | D36: 3.86 | E36: 1.66 | F36: NO ✓
B37: Mild Stress: NOI -10% | C37: KES -0.0bn | D37: 3.48 | E37: 1.49 | F37: NO ✓
B38: Moderate Stress: NOI -20% | C38: KES -0.0bn | D38: 3.09 | E38: 1.33 | F38: NO ✓
B39: Severe Stress: NOI -30% | C39: KES -0.0bn | D39: 2.7 | E39: 1.16 | F39: YES ✗ — COVENANT BREACH
B40: Extreme: NOI -50% | C40: KES -0.0bn | D40: 1.93 | E40: 0.83 | F40: YES ✗ — COVENANT BREACH
B41: NPL surge: +5pp extra impairment | C41: KES -0.0bn | D41: 3.04 | E41: 0.93 | F41: YES ✗ — COVENANT BREACH

Sheet Lending Recommendation
A1: LENDING RECOMMENDATION — CREDIT COMMITTEE SUBMISSION
A2: NCBA Group PLC | KES 5.0 Billion Senior Unsecured Facility
A4: A. CREDIT DECISION
B5: ✅ RECOMMENDED: APPROVE
B6: NCBA Group PLC presents as a high-quality, investment-grade borrower. The credit case rests on: (1) strong and consistent earnings power (PAT KES 23.4bn, ROE 19.7%); (2) exceptional liquidity (cash + govts cover 53.7% of deposits); (3) conservative gearing (net cash position); (4) improving asset quality trajectory; and (5) regulatory capital well above minimums. The proposed exposure of KES 5.0bn is immaterial relative to the borrower's balance sheet.
A8: B. FACILITY TERM SHEET
B9: Facility Type | C9: Senior Unsecured Bilateral Term Loan
B10: Facility Amount | C10: KES 5,000,000,000 (Five Billion Kenya Shillings)
B11: Availability Period | C11: 6 months from signing date
B12: Tenor | C12: 36 months from first drawdown date
B13: Repayment | C13: Bullet repayment at maturity + quarterly interest payments
B14: Interest Rate | C14: CBR + 350 basis points (floating, quarterly reset)
B15: Indicative Rate at Signing | C15: ~13.50% pa (assuming CBR = 10.0%)
B16: Default Rate | C16: Contract rate + 300bps on overdue amounts
B17: Arrangement Fee | C17: 1.00% flat on facility amount (KES 50mn)
B18: Commitment Fee | C18: 0.50% pa on undrawn amounts during availability period
B19: Prepayment | C19: Permitted without penalty with 30 days' notice
B20: Purpose | C20: General corporate; working capital; subsidiary capitalization
... B23: Governing Law | C23: Laws of Kenya; jurisdiction: High Court of Kenya (Commercial Division)
A25: C. FINANCIAL COVENANTS
B26: Covenant | C26: Trigger Level | D26: FY2025 Actual | E26: Headroom
B27: Minimum Capital Adequacy Ratio (CAR) | C27: ≥ 15.5% (CBK min 14.5% + 100bps buffer) | D27: 19.8% | E27: +4.3%
B28: Minimum Tier 1 Capital Ratio | C28: ≥ 12.0% | D28: 16.3% | E28: +4.3%
B29: Maximum NPL Ratio | C29: ≤ 10.0% | D29: 7.4% | E29: 2.6%
B30: Minimum Group Interest Coverage (NOI/Finance Costs) | C30: ≥ 2.50× | D30: 3.86× | E30: +1.36×
B31: Minimum DSCR | C31: ≥ 1.20× | D31: 1.66× | E31: +0.46×
B32: Maximum Gearing (Debt/Equity) | C32: ≤ 0.50× | D32: 0.06× | E32: +0.44×
B33: Minimum Liquidity (Cash+Govts/Deposits) | C33: ≥ 30% | D33: 53.6% | E33: +23.6%
B34: Minimum ROA | C34: ≥ 1.5% | D34: 3.27% | E34: +1.77%
B35: Dividend Restriction (if covenant breach) | C35: Dividends suspended if any covenant breached | D35: N/A — compliant | E35: —
B36: Negative Pledge | C36: No further security over assets without lender consent | D36: Confirmed | E36: —
B37: Cross-Default | C37: Default on other debt > KES 500mn triggers event of default | D37: Confirmed | E37: —
... B40: Material Adverse Change (MAC) Clause | C40: Lender may accelerate on MAC event | D40: Standard | E40: —
A42: D. CONDITIONS PRECEDENT (CPs)
B43: CP 1 | C43: Execution of all facility documentation in agreed form
B44: CP 2 | C44: Certified board resolution approving the facility and authorising signatories
B45: CP 3 | C45: Receipt of latest audited financial statements (FY2025 — Deloitte signed)
B46: CP 4 | C46: Legal opinions from Borrower's counsel confirming due authorization and enforceability
B47: CP 5 | C47: Confirmation of compliance with all financial covenants as at signing date
B48: CP 6 | C48: No material adverse change in financial condition since date of last audited accounts
...

Sheet Sensitivity Analysis
A1: CREDIT SENSITIVITY ANALYSIS — COVENANT HEADROOM STRESS TESTS
A2: Tests covenant compliance across NOI decline, impairment surge and rate shock scenarios
A4: TABLE 1: FACILITY INTEREST COVERAGE (×) — NOI Decline vs Interest Rate on the proposed KES 5.0bn facility
A5: NOI Decline ↓ / Rate → | B5: CBR+200bps | C5: CBR+250bps | D5: CBR+300bps | E5: CBR+350bps | F5: CBR+400bps | G5: CBR+450bps | H5: CBR+500bps
A6: -0% | B6: ='Financial Statements'!$D$10*(1+VALUE($A6))/('Sources and Assumptions'!$C$17*('Sources and Assumptions'!$C$14+VALUE(MID(B$5,5,3))/10000)) -> 119.71992 | C6: ='Financial Statements'!$D$10*(1+VALUE($A6))/('Sources and Assumptions'!$C$17*('Sources and Assumptions'!$C$14+VALUE(MID(C$5,5,3))/10000)) -> 114.93112 | D6: ='Financial Statements'!$D$10*(1+VALUE($A6))/('Sources and Assumptions'!$C$17*('Sources and Assumptions'!$C$14+VALUE(MID(D$5,5,3))/10000)) -> 110.5107 | E6: ='Financial Statements'!$D$10*(1+VALUE($A6))/('Sources and Assumptions'!$C$17*('Sources and Assumptions'!$C$14+VALUE(MID(E$5,5,3))/10000)) -> 106.41771 | F6: ='Financial Statements'!$D$10*(1+VALUE($A6))/('Sources and Assumptions'!$C$17*('Sources and Assumptions'!$C$14+VALUE(MID(F$5,5,3))/10000)) -> 102.61708 | G6: ='Financial Statements'!$D$10*(1+VALUE($A6))/('Sources and Assumptions'!$C$17*('Sources and Assumptions'!$C$14+VALUE(MID(G$5,5,3))/10000)) -> 99.078556 | H6: ='Financial Statements'!$D$10*(1+VALUE($A6))/('Sources and Assumptions'!$C$17*('Sources and Assumptions'!$C$14+VALUE(MID(H$5,5,3))/10000)) -> 95.775937
A7: -5% | B7: ='Financial Statements'!$D$10*(1+VALUE($A7))/('Sources and Assumptions'!$C$17*('Sources and Assumptions'!$C$14+VALUE(MID(B$5,5,3))/10000)) -> 113.73393 | C7: ='Financial Statements'!$D$10*(1+VALUE($A7))/('Sources and Assumptions'!$C$17*('Sources and Assumptions'!$C$14+VALUE(MID(C$5,5,3))/10000)) -> 109.18457 | D7: ='Financial Statements'!$D$10*(1+VALUE($A7))/('Sources and Assumptions'!$C$17*('Sources and Assumptions'!$C$14+VALUE(MID(D$5,5,3))/10000)) -> 104.98516 | E7: ='Financial Statements'!$D$10*(1+VALUE($A7))/('Sources and Assumptions'!$C$17*('Sources and Assumptions'!$C$14+VALUE(MID(E$5,5,3))/10000)) -> 101.09682 | F7: ='Financial Statements'!$D$10*(1+VALUE($A7))/('Sources and Assumptions'!$C$17*('Sources and Assumptions'!$C$14+VALUE(MID(F$5,5,3))/10000)) -> 97.486222 | G7: ='Financial Statements'!$D$10*(1+VALUE($A7))/('Sources and Assumptions'!$C$17*('Sources and Assumptions'!$C$14+VALUE(MID(G$5,5,3))/10000)) -> 94.124628 | H7: ='Financial Statements'!$D$10*(1+VALUE($A7))/('Sources and Assumptions'!$C$17*('Sources and Assumptions'!$C$14+VALUE(MID(H$5,5,3))/10000)) -> 90.98714
A8: -10% | B8: ='Financial Statements'!$D$10*(1+VALUE($A8))/('Sources and Assumptions'!$C$17*('Sources and Assumptions'!$C$14+VALUE(MID(B$5,5,3))/10000)) -> 107.74793 | C8: ='Financial Statements'!$D$10*(1+VALUE($A8))/('Sources and Assumptions'!$C$17*('Sources and Assumptions'!$C$14+VALUE(MID(C$5,5,3))/10000)) -> 103.43801 | D8: ='Financial Statements'!$D$10*(1+VALUE($A8))/('Sources and Assumptions'!$C$17*('Sources and Assumptions'!$C$14+VALUE(MID(D$5,5,3))/10000)) -> 99.459627 | E8: ='Financial Statements'!$D$10*(1+VALUE($A8))/('Sources and Assumptions'!$C$17*('Sources and Assumptions'!$C$14+VALUE(MID(E$5,5,3))/10000)) -> 95.775937 | F8: ='Financial Statements'!$D$10*(1+VALUE($A8))/('Sources and Assumptions'!$C$17*('Sources and Assumptions'!$C$14+VALUE(MID(F$5,5,3))/10000)) -> 92.355368 | G8: ='Financial Statements'!$D$10*(1+VALUE($A8))/('Sources and Assumptions'!$C$17*('Sources and Assumptions'!$C$14+VALUE(MID(G$5,5,3))/10000)) -> 89.1707 | H8: ='Financial Statements'!$D$10*(1+VALUE($A8))/('Sources and Assumptions'!$C$17*('Sources and Assumptions'!$C$14+VALUE(MID(H$5,5,3))/10000)) -> 86.198344
A9: -15% | B9: ='Financial Statements'!$D$10*(1+VALUE($A9))/('Sources and Assumptions'!$C$17*('Sources and Assumptions'!$C$14+VALUE(MID(B$5,5,3))/10000)) -> 101.76193 | C9: ='Financial Statements'!$D$10*(1+VALUE($A9))/('Sources and Assumptions'!$C$17*('Sources and Assumptions'!$C$14+VALUE(MID(C$5,5,3))/10000)) -> 97.691456 | D9: ='Financial Statements'!$D$10*(1+VALUE($A9))/('Sources and Assumptions'!$C$17*('Sources and Assumptions'!$C$14+VALUE(MID(D$5,5,3))/10000)) -> 93.934092 | E9: ='Financial Statements'!$D$10*(1+VALUE($A9))/('Sources and Assumptions'!$C$17*('Sources and Assumptions'!$C$14+VALUE(MID(E$5,5,3))/10000)) -> 90.455052 | F9: ='Financial Statements'!$D$10*(1+VALUE($A9))/('Sources and Assumptions'!$C$17*('Sources and Assumptions'!$C$14+VALUE(MID(F$5,5,3))/10000)) -> 87.224514 | G9: ='Financial Statements'!$D$10*(1+VALUE($A9))/('Sources and Assumptions'!$C$17*('Sources and Assumptions'!$C$14+VALUE(MID(G$5,5,3))/10000)) -> 84.216772 | H9: ='Financial Statements'!$D$10*(1+VALUE($A9))/('Sources and Assumptions'!$C$17*('Sources and Assumptions'!$C$14+VALUE(MID(H$5,5,3))/10000)) -> 81.409547
A10: -20% | B10: ='Financial Statements'!$D$10*(1+VALUE($A10))/('Sources and Assumptions'!$C$17*('Sources and Assumptions'!$C$14+VALUE(MID(B$5,5,3))/10000)) -> 95.775937 | C10: ='Financial Statements'!$D$10*(1+VALUE($A10))/('Sources and Assumptions'!$C$17*('Sources and Assumptions'!$C$14+VALUE(MID(C$5,5,3))/10000)) -> 91.9449 | D10: ='Financial Statements'!$D$10*(1+VALUE($A10))/('Sources and Assumptions'!$C$17*('Sources and Assumptions'!$C$14+VALUE(MID(D$5,5,3))/10000)) -> 88.408558 | E10: ='Financial Statements'!$D$10*(1+VALUE($A10))/('Sources and Assumptions'!$C$17*('Sources and Assumptions'!$C$14+VALUE(MID(E$5,5,3))/10000)) -> 85.134167 | F10: ='Financial Statements'!$D$10*(1+VALUE($A10))/('Sources and Assumptions'!$C$17*('Sources and Assumptions'!$C$14+VALUE(MID(F$5,5,3))/10000)) -> 82.093661 | G10: ='Financial Statements'!$D$10*(1+VALUE($A10))/('Sources and Assumptions'!$C$17*('Sources and Assumptions'!$C$14+VALUE(MID(G$5,5,3))/10000)) -> 79.262845 | H10: ='Financial Statements'!$D$10*(1+VALUE($A10))/('Sources and Assumptions'!$C$17*('Sources and Assumptions'!$C$14+VALUE(MID(H$5,5,3))/10000)) -> 76.62075
A11: -25% | B11: ='Financial Statements'!$D$10*(1+VALUE($A11))/('Sources and Assumptions'!$C$17*('Sources and Assumptions'!$C$14+VALUE(MID(B$5,5,3))/10000)) -> 89.789941 | C11: ='Financial Statements'!$D$10*(1+VALUE($A11))/('Sources and Assumptions'!$C$17*('Sources and Assumptions'!$C$14+VALUE(MID(C$5,5,3))/10000)) -> 86.198344 | D11: ='Financial Statements'!$D$10*(1+VALUE($A11))/('Sources and Assumptions'!$C$17*('Sources and Assumptions'!$C$14+VALUE(MID(D$5,5,3))/10000)) -> 82.883023 | E11: ='Financial Statements'!$D$10*(1+VALUE($A11))/('Sources and Assumptions'!$C$17*('Sources and Assumptions'!$C$14+VALUE(MID(E$5,5,3))/10000)) -> 79.813281 | F11: ='Financial Statements'!$D$10*(1+VALUE($A11))/('Sources and Assumptions'!$C$17*('Sources and Assumptions'!$C$14+VALUE(MID(F$5,5,3))/10000)) -> 76.962807 | G11: ='Financial Statements'!$D$10*(1+VALUE($A11))/('Sources and Assumptions'!$C$17*('Sources and Assumptions'!$C$14+VALUE(MID(G$5,5,3))/10000)) -> 74.308917 | H11: ='Financial Statements'!$D$10*(1+VALUE($A11))/('Sources and Assumptions'!$C$17*('Sources and Assumptions'!$C$14+VALUE(MID(H$5,5,3))/10000)) -> 71.831953
A12: -30% | B12: ='Financial Statements'!$D$10*(1+VALUE($A12))/('Sources and Assumptions'!$C$17*('Sources and Assumptions'!$C$14+VALUE(MID(B$5,5,3))/10000)) -> 83.803945 | C12: ='Financial Statements'!$D$10*(1+VALUE($A12))/('Sources and Assumptions'!$C$17*('Sources and Assumptions'!$C$14+VALUE(MID(C$5,5,3))/10000)) -> 80.451787 | D12: ='Financial Statements'!$D$10*(1+VALUE($A12))/('Sources and Assumptions'!$C$17*('Sources and Assumptions'!$C$14+VALUE(MID(D$5,5,3))/10000)) -> 77.357488 | E12: ='Financial Statements'!$D$10*(1+VALUE($A12))/('Sources and Assumptions'!$C$17*('Sources and Assumptions'!$C$14+VALUE(MID(E$5,5,3))/10000)) -> 74.492396 | F12: ='Financial Statements'!$D$10*(1+VALUE($A12))/('Sources and Assumptions'!$C$17*('Sources and Assumptions'!$C$14+VALUE(MID(F$5,5,3))/10000)) -> 71.831953 | G12: ='Financial Statements'!$D$10*(1+VALUE($A12))/('Sources and Assumptions'!$C$17*('Sources and Assumptions'!$C$14+VALUE(MID(G$5,5,3))/10000)) -> 69.354989 | H12: ='Financial Statements'!$D$10*(1+VALUE($A12))/('Sources and Assumptions'!$C$17*('Sources and Assumptions'!$C$14+VALUE(MID(H$5,5,3))/10000)) -> 67.043156
A13: Basis: Group NOI ÷ annual interest on the proposed KES 5.0bn facility only (CBR + spread; CBR per Sources and Assumptions). This is NOT the Group Interest Coverage on Ratio Analysis (NOI ÷ total Group finance costs; 3.86× in FY2025), so the two are not comparable. Group-level coverage under NOI stress is on Risk Assessment, Section C.
A15: TABLE 2: PAT (KES bn) — NPL Ratio vs Credit Loss Severity
A16: NPL Ratio ↓ / Loss Given Default → | B16: LGD 30% | C16: LGD 35% | D16: LGD 40% | E16: LGD 45% | F16: LGD 50% | G16: LGD 55% | H16: LGD 60%
A17: NPL 5% | B17: 0 | C17: 0 | D17: 0 | E17: 0 | F17: 0 | G17: 0 | H17: 0
A18: NPL 7% | B18: 0 | C18: 0 | D18: 0 | E18: 0 | F18: 0 | G18: 0 | H18: 0
A19: NPL 9% | B19: 0 | C19: 0 | D19: 0 | E19: 0 | F19: 0 | G19: 0 | H19: 0
A20: NPL 10% | B20: 0 | C20: 0 | D20: 0 | E20: 0 | F20: 0 | G20: 0 | H20: 0
A21: NPL 12% | B21: 0 | C21: 0 | D21: 0 | E21: 0 | F21: 0 | G21: 0 | H21: 0
A22: NPL 15% | B22: 0 | C22: 0 | D22: 0 | E22: 0 | F22: 0 | G22: 0 | H22: 0
A23: NPL 18% | B23: 0 | C23: 0 | D23: 0 | E23: 0 | F23: 0 | G23: 0 | H23: 0
A26: TABLE 3: DSCR (×) — Covenant Compliance Under Combined Stress (Covenant: ≥ 1.20×)
A27: NOI Decline ↓ / Additional Impair. → | B27: +KES 0bn | C27: +KES 2bn | D27: +KES 4bn | E27: +KES 6bn | F27: +KES 8bn | G27: +KES 10bn | H27: +KES 12bn
A28: NOI -0% | B28: 1.61 | C28: 1.52 | D28: 1.42 | E28: 1.33 | F28: 1.24 | G28: 1.14 | H28: 1.05
A29: NOI -5% | B29: 1.53 | C29: 1.43 | D29: 1.34 | E29: 1.25 | F29: 1.16 | G29: 1.06 | H29: 0.97
A30: NOI -10% | B30: 1.45 | C30: 1.35 | D30: 1.26 | E30: 1.17 | F30: 1.08 | G30: 0.98 | H30: 0.89
A31: NOI -15% | B31: 1.37 | C31: 1.27 | D31: 1.18 | E31: 1.09 | F31: 1 | G31: 0.9 | H31: 0.81
A32: NOI -20% | B32: 1.29 | C32: 1.19 | D32: 1.1 | E32: 1.01 | F32: 0.92 | G32: 0.82 | H32: 0.73
A33: NOI -25% | B33: 1.21 | C33: 1.11 | D33: 1.02 | E33: 0.93 | F33: 0.84 | G33: 0.74 | H33: 0.65
A34: NOI -30% | B34: 1.13 | C34: 1.03 | D34: 0.94 | E34: 0.85 | F34: 0.75 | G34: 0.66 | H34: 0.57
A36: LEGEND
A37: GREEN — Covenant compliant with comfortable headroom (>20% buffer)
A38: YELLOW — Covenant at risk — watch trigger (10–20% buffer)
A39: RED — Covenant breach — event of default triggered

Sheet Sources and Assumptions
A1: SOURCES AND ASSUMPTIONS — NCBA GROUP PLC CREDIT CASE STUDY
A2: Illustrative case study based on public annual reports. Not a real credit decision.
A4: A. SOURCES (PUBLIC INFORMATION)
A5: # | B5: Source | C5: Period | D5: Where used in this model
A6: 1 | B6: NCBA Group PLC — Annual Report & Audited Financial Statements | C6: FY2023 | D6: Financial Statements (FY2023 column); Ratio Analysis (FY2023); trend and CAGR calculations
A7: 2 | B7: NCBA Group PLC — Annual Report & Audited Financial Statements | C7: FY2024 | D7: Financial Statements (FY2024 column); Ratio Analysis (FY2024); year-on-year comparisons
A8: 3 | B8: NCBA Group PLC — Annual Report & Audited Financial Statements | C8: FY2025 (year ended 31 Dec 2025) | D8: Financial Statements (FY2025 column); Ratio Analysis (FY2025); Credit Memo; Borrower Profile; all stress tests
A9: 4 | B9: Analyst estimates / illustrative inputs | C9: n/a | D9: NSFR and LCR (marked "est."), top-20 loan concentration, employee count, RAROC range, comparable-transaction pricing, and the facility terms themselves. These are not taken from the annual reports.
A10: 5 | B10: Regulatory minima quoted in covenants (CAR 14.5%, Tier 1 10.5%) | C10: As assumed in the model | D10: Ratio Analysis benchmarks; Lending Recommendation covenant triggers. Verify against current CBK prudential guidelines before relying on them.
A12: B. FACILITY & PRICING ASSUMPTIONS (blue = input; change here and linked cells update)
A13: # | B13: Assumption | C13: Value | D13: Basis / notes
A14: B1 | B14: Central Bank Rate (CBR) | C14: 0.1 | D14: Assumed at 10.0% for illustration. This is a modelling assumption, not a forecast or the prevailing CBK rate on any given date. Drives Sensitivity Analysis Table 1.
A15: B2 | B15: Credit margin over CBR | C15: 0.035 | D15: 350 bps, floating, quarterly reset (see Lending Recommendation, Section E for build-up)
A16: B3 | B16: All-in interest rate | C16: =C14+C15 -> 0.135 | D16: CBR + margin; ties to the ~13.5% pa quoted on Credit Memo and Lending Recommendation
A17: B4 | B17: Facility amount (KES '000) | C17: 5000000 | D17: KES 5.0 billion, in KES '000 to match the Financial Statements sheet
A18: B5 | B18: Tenor (months) | C18: 36 | D18: From first drawdown; bullet repayment at maturity, quarterly interest
A19: B6 | B19: Availability period (months) | C19: 6 | D19: Commitment fee accrues during this period only
A20: B7 | B20: Arrangement fee (% flat of facility) | C20: 0.01 | D20: 1.00% flat; KES 50mn on KES 5.0bn. Payable as a condition precedent.
A21: B8 | B21: Commitment fee (% pa on undrawn) | C21: 0.005 | D21: 0.50% pa on undrawn amounts during the availability period
A22: B9 | B22: Default margin (over contract rate) | C22: 0.03 | D22: +300 bps on overdue amounts
A24: C. YEAR-1 REVENUE CHECK (KES mn) — ties to Lending Recommendation, Section E
A25: # | B25: Component | C25: KES mn | D25: Calculation
A26: C1 | B26: Interest income | C26: =C17/1000*C16 -> 675 | D26: Facility × all-in rate × 12 months (assumes fully drawn for the year)
A27: C2 | B27: Arrangement fee | C27: =C17/1000*C20 -> 50 | D27: Facility × arrangement fee %
A28: C3 | B28: Commitment fee | C28: =C17/1000*C21*C19/12 -> 12.5 | D28: Facility × commitment fee % × availability period ÷ 12 (assumes fully undrawn during availability period)
A29: C4 | B29: Total Year-1 revenue | C29: =SUM(C26:C28) -> 737.5 | D29: Memo figure on Lending Recommendation: KES 737.5mn
A30: C5 | B30: Simplification | D30: Interest assumes the full facility is drawn for 12 months while the commitment fee assumes it is undrawn for 6 months. The total is therefore an upper-bound illustration, not a drawdown schedule.
A32: D. INTEREST COVERAGE — TWO DIFFERENT MEASURES
A33: # | B33: Measure | C33: FY2025 (base case) | D33: Definition
A34: D1 | B34: Group interest coverage | C34: ='Ratio Analysis'!D6 -> 3.8619 | D34: Group Net Operating Income ÷ total Group finance costs. Used for the covenant test (≥ 2.50×), Ratio Analysis and the Risk Assessment stress test.
A35: D2 | B35: Facility interest coverage | C35: ='Sensitivity Analysis'!E6 -> 106.41771 | D35: Group Net Operating Income ÷ annual interest on the proposed KES 5.0bn facility only (at CBR + 350 bps). Used in Sensitivity Analysis Table 1. Far larger than D1 because the denominator is one facility, not the whole Group funding cost.
A36: D3 | B36: Comparability | D36: The two measures answer different questions and should not be compared directly. Group coverage tests the borrower's overall resilience; facility coverage shows how small the new debt is relative to earnings.
A38: E. DATA CONVENTIONS & LIMITATIONS
A39: E1 | B39: Financial Statements and Ratio Analysis are in KES '000 unless a label says otherwise.
A40: E2 | B40: Ratios are entered values taken from the analyst's workings, except where a cell is a formula. Estimated ratios are labelled "est.".
A41: E3 | B41: Some FY2023 inputs are rounded and have not been reconciled line-by-line to the annual report.
A42: E4 | B42: The facility, its terms, fees, covenants and the credit decision are hypothetical. "Hypothetical Lender" is a placeholder and does not refer to any real institution.
A43: E5 | B43: This workbook is an educational exercise and is not investment, credit or legal advice.
